Workbook

Sheet Generale
A1: Anno Riferimento | B1: 2016
A3: Nominativo / Risorsa | B3: CF | C3: Ruolo | D3: Fascia di Livello | E3: Costo Orario (€/h) | F3: Ore Anno 1 | G3: Ore Anno 2 | H3: Ore Anno 3 | I3: Ore Anno 4 | J3: Totale Ore | L3: Fascia di livello | M3: IMP | N3: IMP-24 | O3: UNI | P3: UNI-24 | Q3: EPR | R3: EPR-24
A4: Andretto Elia | B4: NDRLEI98H26E063K | C4: CTER | D4: BASSO | E4: =_xlfn.IFNA(INDEX($Q$5:$R$7,MATCH(D4,$L$5:$L$7,0),MATCH($B$1,$Q$4:$R$4,0)),0) -> 29 | F4: =SUMIFS('Ore-Mese'!$D:$D,'Ore-Mese'!$A:$A,Generale!$A4,'Ore-Mese'!$B:$B,VALUE(RIGHT(Generale!F$3,1))) -> 158.4 | G4: =SUMIFS('Ore-Mese'!$D:$D,'Ore-Mese'!$A:$A,Generale!$A4,'Ore-Mese'!$B:$B,VALUE(RIGHT(Generale!G$3,1))) -> 89.1 | H4: =SUMIFS('Ore-Mese'!$D:$D,'Ore-Mese'!$A:$A,Generale!$A4,'Ore-Mese'!$B:$B,VALUE(RIGHT(Generale!H$3,1))) -> 89.1 | I4: =SUMIFS('Ore-Mese'!$D:$D,'Ore-Mese'!$A:$A,Generale!$A4,'Ore-Mese'!$B:$B,VALUE(RIGHT(Generale!I$3,1))) -> 158.4 | J4: =SUM(F4:I4) -> 495 | L4: Anno riferimento costi orari | M4: 2016 | N4: 2024 | O4: 2016 | P4: 2024 | Q4: 2016 | R4: 2024
A5: Bozzi Roberto | B5: BZZRRT67H19F205U | C5: CTER | D5: BASSO | E5: =_xlfn.IFNA(INDEX($Q$5:$R$7,MATCH(D5,$L$5:$L$7,0),MATCH($B$1,$Q$4:$R$4,0)),0) -> 29 | F5: =SUMIFS('Ore-Mese'!$D:$D,'Ore-Mese'!$A:$A,Generale!$A5,'Ore-Mese'!$B:$B,VALUE(RIGHT(Generale!F$3,1))) -> 158.4 | G5: =SUMIFS('Ore-Mese'!$D:$D,'Ore-Mese'!$A:$A,Generale!$A5,'Ore-Mese'!$B:$B,VALUE(RIGHT(Generale!G$3,1))) -> 89.1 | H5: =SUMIFS('Ore-Mese'!$D:$D,'Ore-Mese'!$A:$A,Generale!$A5,'Ore-Mese'!$B:$B,VALUE(RIGHT(Generale!H$3,1))) -> 89.1 | I5: =SUMIFS('Ore-Mese'!$D:$D,'Ore-Mese'!$A:$A,Generale!$A5,'Ore-Mese'!$B:$B,VALUE(RIGHT(Generale!I$3,1))) -> 158.4 | J5: =SUM(F5:I5) -> 495 | L5: ALTO | M5: 75 | N5: 83 | O5: 73 | P5: 81 | Q5: 55 | R5: 61
A6: Caimmi Marco | B6: CMMMRC68C12F205K | C6: I ricercatore | D6: ALTO | E6: =_xlfn.IFNA(INDEX($Q$5:$R$7,MATCH(D6,$L$5:$L$7,0),MATCH($B$1,$Q$4:$R$4,0)),0) -> 55 | F6: =SUMIFS('Ore-Mese'!$D:$D,'Ore-Mese'!$A:$A,Generale!$A6,'Ore-Mese'!$B:$B,VALUE(RIGHT(Generale!F$3,1))) -> 550 | G6: =SUMIFS('Ore-Mese'!$D:$D,'Ore-Mese'!$A:$A,Generale!$A6,'Ore-Mese'!$B:$B,VALUE(RIGHT(Generale!G$3,1))) -> 132 | H6: =SUMIFS('Ore-Mese'!$D:$D,'Ore-Mese'!$A:$A,Generale!$A6,'Ore-Mese'!$B:$B,VALUE(RIGHT(Generale!H$3,1))) -> 0 | I6: =SUMIFS('Ore-Mese'!$D:$D,'Ore-Mese'!$A:$A,Generale!$A6,'Ore-Mese'!$B:$B,VALUE(RIGHT(Generale!I$3,1))) -> 0 | J6: =SUM(F6:I6) -> 682 | L6: MEDIO | M6: 43 | N6: 47 | O6: 48 | P6: 53 | Q6: 33 | R6: 36
A7: Chizzoli Guido | B7: CHZGDU78R25D142Y | C7: Ricercatore III | D7: MEDIO | E7: =_xlfn.IFNA(INDEX($Q$5:$R$7,MATCH(D7,$L$5:$L$7,0),MATCH($B$1,$Q$4:$R$4,0)),0) -> 33 | F7: =SUMIFS('Ore-Mese'!$D:$D,'Ore-Mese'!$A:$A,Generale!$A7,'Ore-Mese'!$B:$B,VALUE(RIGHT(Generale!F$3,1))) -> 126.5 | G7: =SUMIFS('Ore-Mese'!$D:$D,'Ore-Mese'!$A:$A,Generale!$A7,'Ore-Mese'!$B:$B,VALUE(RIGHT(Generale!G$3,1))) -> 0 | H7: =SUMIFS('Ore-Mese'!$D:$D,'Ore-Mese'!$A:$A,Generale!$A7,'Ore-Mese'!$B:$B,VALUE(RIGHT(Generale!H$3,1))) -> 0 | I7: =SUMIFS('Ore-Mese'!$D:$D,'Ore-Mese'!$A:$A,Generale!$A7,'Ore-Mese'!$B:$B,VALUE(RIGHT(Generale!I$3,1))) -> 0 | J7: =SUM(F7:I7) -> 126.5 | L7: BASSO | M7: 27 | N7: 30 | O7: 31 | P7: 34 | Q7: 29 | R7: 32
A8: Dinon Tito | B8: DNNTTI86M09C933W | C8: CTER | D8: BASSO | E8: =_xlfn.IFNA(INDEX($Q$5:$R$7,MATCH(D8,$L$5:$L$7,0),MATCH($B$1,$Q$4:$R$4,0)),0) -> 29 | F8: =SUMIFS('Ore-Mese'!$D:$D,'Ore-Mese'!$A:$A,Generale!$A8,'Ore-Mese'!$B:$B,VALUE(RIGHT(Generale!F$3,1))) -> 158.4 | G8: =SUMIFS('Ore-Mese'!$D:$D,'Ore-Mese'!$A:$A,Generale!$A8,'Ore-Mese'!$B:$B,VALUE(RIGHT(Generale!G$3,1))) -> 158.4 | H8: =SUMIFS('Ore-Mese'!$D:$D,'Ore-Mese'!$A:$A,Generale!$A8,'Ore-Mese'!$B:$B,VALUE(RIGHT(Generale!H$3,1))) -> 113.3 | I8: =SUMIFS('Ore-Mese'!$D:$D,'Ore-Mese'!$A:$A,Generale!$A8,'Ore-Mese'!$B:$B,VALUE(RIGHT(Generale!I$3,1))) -> 89.1 | J8: =SUM(F8:I8) -> 519.2
A9: Mottura Stefano | B9: MTTSFN70L14F205T | C9: I Tecnologo | D9: ALTO | E9: =_xlfn.IFNA(INDEX($Q$5:$R$7,MATCH(D9,$L$5:$L$7,0),MATCH($B$1,$Q$4:$R$4,0)),0) -> 55 | F9: =SUMIFS('Ore-Mese'!$D:$D,'Ore-Mese'!$A:$A,Generale!$A9,'Ore-Mese'!$B:$B,VALUE(RIGHT(Generale!F$3,1))) -> 599.5 | G9: =SUMIFS('Ore-Mese'!$D:$D,'Ore-Mese'!$A:$A,Generale!$A9,'Ore-Mese'!$B:$B,VALUE(RIGHT(Generale!G$3,1))) -> 599.5 | H9: =SUMIFS('Ore-Mese'!$D:$D,'Ore-Mese'!$A:$A,Generale!$A9,'Ore-Mese'!$B:$B,VALUE(RIGHT(Generale!H$3,1))) -> 430.1 | I9: =SUMIFS('Ore-Mese'!$D:$D,'Ore-Mese'!$A:$A,Generale!$A9,'Ore-Mese'!$B:$B,VALUE(RIGHT(Generale!I$3,1))) -> 338.8 | J9: =SUM(F9:I9) -> 1967.9
A10: Pedrocchi Nicola | B10: PDRNCL79H26E333U | C10: Dir. Ricerca | D10: ALTO | E10: =_xlfn.IFNA(INDEX($Q$5:$R$7,MATCH(D10,$L$5:$L$7,0),MATCH($B$1,$Q$4:$R$4,0)),0) -> 55 | F10: =SUMIFS('Ore-Mese'!$D:$D,'Ore-Mese'!$A:$A,Generale!$A10,'Ore-Mese'!$B:$B,VALUE(RIGHT(Generale!F$3,1))) -> 1386 | G10: =SUMIFS('Ore-Mese'!$D:$D,'Ore-Mese'!$A:$A,Generale!$A10,'Ore-Mese'!$B:$B,VALUE(RIGHT(Generale!G$3,1))) -> 1386 | H10: =SUMIFS('Ore-Mese'!$D:$D,'Ore-Mese'!$A:$A,Generale!$A10,'Ore-Mese'!$B:$B,VALUE(RIGHT(Generale!H$3,1))) -> 1104.4 | I10: =SUMIFS('Ore-Mese'!$D:$D,'Ore-Mese'!$A:$A,Generale!$A10,'Ore-Mese'!$B:$B,VALUE(RIGHT(Generale!I$3,1))) -> 660 | J10: =SUM(F10:I10) -> 4536.4
A11: Silva Fabrizio | B11: SLVFRZ80S19L872K | C11: Tecnologo III | D11: MEDIO | E11: =_xlfn.IFNA(INDEX($Q$5:$R$7,MATCH(D11,$L$5:$L$7,0),MATCH($B$1,$Q$4:$R$4,0)),0) -> 33 | F11: =SUMIFS('Ore-Mese'!$D:$D,'Ore-Mese'!$A:$A,Generale!$A11,'Ore-Mese'!$B:$B,VALUE(RIGHT(Generale!F$3,1))) -> 126.5 | G11: =SUMIFS('Ore-Mese'!$D:$D,'Ore-Mese'!$A:$A,Generale!$A11,'Ore-Mese'!$B:$B,VALUE(RIGHT(Generale!G$3,1))) -> 0 | H11: =SUMIFS('Ore-Mese'!$D:$D,'Ore-Mese'!$A:$A,Generale!$A11,'Ore-Mese'!$B:$B,VALUE(RIGHT(Generale!H$3,1))) -> 0 | I11: =SUMIFS('Ore-Mese'!$D:$D,'Ore-Mese'!$A:$A,Generale!$A11,'Ore-Mese'!$B:$B,VALUE(RIGHT(Generale!I$3,1))) -> 0 | J11: =SUM(F11:I11) -> 126.5
A12: Spena Pier Raffaele | B12: SPNPRF70T12F839E | C12: CTER | D12: BASSO | E12: =_xlfn.IFNA(INDEX($Q$5:$R$7,MATCH(D12,$L$5:$L$7,0),MATCH($B$1,$Q$4:$R$4,0)),0) -> 29 | F12: =SUMIFS('Ore-Mese'!$D:$D,'Ore-Mese'!$A:$A,Generale!$A12,'Ore-Mese'!$B:$B,VALUE(RIGHT(Generale!F$3,1))) -> 158.4 | G12: =SUMIFS('Ore-Mese'!$D:$D,'Ore-Mese'!$A:$A,Generale!$A12,'Ore-Mese'!$B:$B,VALUE(RIGHT(Generale!G$3,1))) -> 158.4 | H12: =SUMIFS('Ore-Mese'!$D:$D,'Ore-Mese'!$A:$A,Generale!$A12,'Ore-Mese'!$B:$B,VALUE(RIGHT(Generale!H$3,1))) -> 113.3 | I12: =SUMIFS('Ore-Mese'!$D:$D,'Ore-Mese'!$A:$A,Generale!$A12,'Ore-Mese'!$B:$B,VALUE(RIGHT(Generale!I$3,1))) -> 89.1 | J12: =SUM(F12:I12) -> 519.2
A13: Villagrossi Enrico | B13: VLLNRC86R08E897T | C13: Ricercatore | D13: MEDIO | E13: =_xlfn.IFNA(INDEX($Q$5:$R$7,MATCH(D13,$L$5:$L$7,0),MATCH($B$1,$Q$4:$R$4,0)),0) -> 33 | F13: =SUMIFS('Ore-Mese'!$D:$D,'Ore-Mese'!$A:$A,Generale!$A13,'Ore-Mese'!$B:$B,VALUE(RIGHT(Generale!F$3,1))) -> 469.3 | G13: =SUMIFS('Ore-Mese'!$D:$D,'Ore-Mese'!$A:$A,Generale!$A13,'Ore-Mese'!$B:$B,VALUE(RIGHT(Generale!G$3,1))) -> 254.1 | H13: =SUMIFS('Ore-Mese'!$D:$D,'Ore-Mese'!$A:$A,Generale!$A13,'Ore-Mese'!$B:$B,VALUE(RIGHT(Generale!H$3,1))) -> 181.5 | I13: =SUMIFS('Ore-Mese'!$D:$D,'Ore-Mese'!$A:$A,Generale!$A13,'Ore-Mese'!$B:$B,VALUE(RIGHT(Generale!I$3,1))) -> 0 | J13: =SUM(F13:I13) -> 904.9
A14: Contratto di Ricerca 1 | C14: Ricercatore | D14: MEDIO | E14: =_xlfn.IFNA(INDEX($Q$5:$R$7,MATCH(D14,$L$5:$L$7,0),MATCH($B$1,$Q$4:$R$4,0)),0) -> 33 | F14: =SUMIFS('Ore-Mese'!$D:$D,'Ore-Mese'!$A:$A,Generale!$A14,'Ore-Mese'!$B:$B,VALUE(RIGHT(Generale!F$3,1))) -> 630 | G14: =SUMIFS('Ore-Mese'!$D:$D,'Ore-Mese'!$A:$A,Generale!$A14,'Ore-Mese'!$B:$B,VALUE(RIGHT(Generale!G$3,1))) -> 1386 | H14: =SUMIFS('Ore-Mese'!$D:$D,'Ore-Mese'!$A:$A,Generale!$A14,'Ore-Mese'!$B:$B,VALUE(RIGHT(Generale!H$3,1))) -> 1100 | I14: =SUMIFS('Ore-Mese'!$D:$D,'Ore-Mese'!$A:$A,Generale!$A14,'Ore-Mese'!$B:$B,VALUE(RIGHT(Generale!I$3,1))) -> 700 | J14: =SUM(F14:I14) -> 3816
A15: Contratto di Ricerca 2 | C15: Ricercatore | D15: MEDIO | E15: =_xlfn.IFNA(INDEX($Q$5:$R$7,MATCH(D15,$L$5:$L$7,0),MATCH($B$1,$Q$4:$R$4,0)),0) -> 33 | F15: =SUMIFS('Ore-Mese'!$D:$D,'Ore-Mese'!$A:$A,Generale!$A15,'Ore-Mese'!$B:$B,VALUE(RIGHT(Generale!F$3,1))) -> 0 | G15: =SUMIFS('Ore-Mese'!$D:$D,'Ore-Mese'!$A:$A,Generale!$A15,'Ore-Mese'!$B:$B,VALUE(RIGHT(Generale!G$3,1))) -> 560 | H15: =SUMIFS('Ore-Mese'!$D:$D,'Ore-Mese'!$A:$A,Generale!$A15,'Ore-Mese'!$B:$B,VALUE(RIGHT(Generale!H$3,1))) -> 693 | I15: =SUMIFS('Ore-Mese'!$D:$D,'Ore-Mese'!$A:$A,Generale!$A15,'Ore-Mese'!$B:$B,VALUE(RIGHT(Generale!I$3,1))) -> 990 | J15: =SUM(F15:I15) -> 2243
A16: Incarico di Ricerca 1 | C16: Ricercatore | D16: MEDIO | E16: =_xlfn.IFNA(INDEX($Q$5:$R$7,MATCH(D16,$L$5:$L$7,0),MATCH($B$1,$Q$4:$R$4,0)),0) -> 33 | F16: =SUMIFS('Ore-Mese'!$D:$D,'Ore-Mese'!$A:$A,Generale!$A16,'Ore-Mese'!$B:$B,VALUE(RIGHT(Generale!F$3,1))) -> 504 | G16: =SUMIFS('Ore-Mese'!$D:$D,'Ore-Mese'!$A:$A,Generale!$A16,'Ore-Mese'!$B:$B,VALUE(RIGHT(Generale!G$3,1))) -> 1386 | H16: =SUMIFS('Ore-Mese'!$D:$D,'Ore-Mese'!$A:$A,Generale!$A16,'Ore-Mese'!$B:$B,VALUE(RIGHT(Generale!H$3,1))) -> 693 | I16: =SUMIFS('Ore-Mese'!$D:$D,'Ore-Mese'!$A:$A,Generale!$A16,'Ore-Mese'!$B:$B,VALUE(RIGHT(Generale!I$3,1))) -> 693 | J16: =SUM(F16:I16) -> 3276
A17: Incarico di Ricerca 2 | C17: Ricercatore | D17: MEDIO | E17: =_xlfn.IFNA(INDEX($Q$5:$R$7,MATCH(D17,$L$5:$L$7,0),MATCH($B$1,$Q$4:$R$4,0)),0) -> 33 | F17: =SUMIFS('Ore-Mese'!$D:$D,'Ore-Mese'!$A:$A,Generale!$A17,'Ore-Mese'!$B:$B,VALUE(RIGHT(Generale!F$3,1))) -> 504 | G17: =SUMIFS('Ore-Mese'!$D:$D,'Ore-Mese'!$A:$A,Generale!$A17,'Ore-Mese'!$B:$B,VALUE(RIGHT(Generale!G$3,1))) -> 1386 | H17: =SUMIFS('Ore-Mese'!$D:$D,'Ore-Mese'!$A:$A,Generale!$A17,'Ore-Mese'!$B:$B,VALUE(RIGHT(Generale!H$3,1))) -> 693 | I17: =SUMIFS('Ore-Mese'!$D:$D,'Ore-Mese'!$A:$A,Generale!$A17,'Ore-Mese'!$B:$B,VALUE(RIGHT(Generale!I$3,1))) -> 693 | J17: =SUM(F17:I17) -> 3276
A18: Fontana Gianmauro | C18: Ricercatore | D18: MEDIO | E18: =_xlfn.IFNA(INDEX($Q$5:$R$7,MATCH(D18,$L$5:$L$7,0),MATCH($B$1,$Q$4:$R$4,0)),0) -> 33 | F18: =SUMIFS('Ore-Mese'!$D:$D,'Ore-Mese'!$A:$A,Generale!$A18,'Ore-Mese'!$B:$B,VALUE(RIGHT(Generale!F$3,1))) -> 825 | G18: =SUMIFS('Ore-Mese'!$D:$D,'Ore-Mese'!$A:$A,Generale!$A18,'Ore-Mese'!$B:$B,VALUE(RIGHT(Generale!G$3,1))) -> 0 | H18: =SUMIFS('Ore-Mese'!$D:$D,'Ore-Mese'!$A:$A,Generale!$A18,'Ore-Mese'!$B:$B,VALUE(RIGHT(Generale!H$3,1))) -> 0 | I18: =SUMIFS('Ore-Mese'!$D:$D,'Ore-Mese'!$A:$A,Generale!$A18,'Ore-Mese'!$B:$B,VALUE(RIGHT(Generale!I$3,1))) -> 0 | J18: =SUM(F18:I18) -> 825
E19: =_xlfn.IFNA(INDEX($Q$5:$R$7,MATCH(D19,$L$5:$L$7,0),MATCH($B$1,$Q$4:$R$4,0)),0) -> 0 | F19: =SUMIFS('Ore-Mese'!$D:$D,'Ore-Mese'!$A:$A,Generale!$A19,'Ore-Mese'!$B:$B,VALUE(RIGHT(Generale!F$3,1))) -> 0 | G19: =SUMIFS('Ore-Mese'!$D:$D,'Ore-Mese'!$A:$A,Generale!$A19,'Ore-Mese'!$B:$B,VALUE(RIGHT(Generale!G$3,1))) -> 0 | H19: =SUMIFS('Ore-Mese'!$D:$D,'Ore-Mese'!$A:$A,Generale!$A19,'Ore-Mese'!$B:$B,VALUE(RIGHT(Generale!H$3,1))) -> 0 | I19: =SUMIFS('Ore-Mese'!$D:$D,'Ore-Mese'!$A:$A,Generale!$A19,'Ore-Mese'!$B:$B,VALUE(RIGHT(Generale!I$3,1))) -> 0 | J19: =SUM(F19:I19) -> 0
E20: =_xlfn.IFNA(INDEX($Q$5:$R$7,MATCH(D20,$L$5:$L$7,0),MATCH($B$1,$Q$4:$R$4,0)),0) -> 0 | F20: =SUMIFS('Ore-Mese'!$D:$D,'Ore-Mese'!$A:$A,Generale!$A20,'Ore-Mese'!$B:$B,VALUE(RIGHT(Generale!F$3,1))) -> 0 | G20: =SUMIFS('Ore-Mese'!$D:$D,'Ore-Mese'!$A:$A,Generale!$A20,'Ore-Mese'!$B:$B,VALUE(RIGHT(Generale!G$3,1))) -> 0 | H20: =SUMIFS('Ore-Mese'!$D:$D,'Ore-Mese'!$A:$A,Generale!$A20,'Ore-Mese'!$B:$B,VALUE(RIGHT(Generale!H$3,1))) -> 0 | I20: =SUMIFS('Ore-Mese'!$D:$D,'Ore-Mese'!$A:$A,Generale!$A20,'Ore-Mese'!$B:$B,VALUE(RIGHT(Generale!I$3,1))) -> 0 | J20: =SUM(F20:I20) -> 0
E21: =_xlfn.IFNA(INDEX($Q$5:$R$7,MATCH(D21,$L$5:$L$7,0),MATCH($B$1,$Q$4:$R$4,0)),0) -> 0 | F21: =SUMIFS('Ore-Mese'!$D:$D,'Ore-Mese'!$A:$A,Generale!$A21,'Ore-Mese'!$B:$B,VALUE(RIGHT(Generale!F$3,1))) -> 0 | G21: =SUMIFS('Ore-Mese'!$D:$D,'Ore-Mese'!$A:$A,Generale!$A21,'Ore-Mese'!$B:$B,VALUE(RIGHT(Generale!G$3,1))) -> 0 | H21: =SUMIFS('Ore-Mese'!$D:$D,'Ore-Mese'!$A:$A,Generale!$A21,'Ore-Mese'!$B:$B,VALUE(RIGHT(Generale!H$3,1))) -> 0 | I21: =SUMIFS('Ore-Mese'!$D:$D,'Ore-Mese'!$A:$A,Generale!$A21,'Ore-Mese'!$B:$B,VALUE(RIGHT(Generale!I$3,1))) -> 0 | J21: =SUM(F21:I21) -> 0
E22: =_xlfn.IFNA(INDEX($Q$5:$R$7,MATCH(D22,$L$5:$L$7,0),MATCH($B$1,$Q$4:$R$4,0)),0) -> 0 | F22: =SUMIFS('Ore-Mese'!$D:$D,'Ore-Mese'!$A:$A,Generale!$A22,'Ore-Mese'!$B:$B,VALUE(RIGHT(Generale!F$3,1))) -> 0 | G22: =SUMIFS('Ore-Mese'!$D:$D,'Ore-Mese'!$A:$A,Generale!$A22,'Ore-Mese'!$B:$B,VALUE(RIGHT(Generale!G$3,1))) -> 0 | H22: =SUMIFS('Ore-Mese'!$D:$D,'Ore-Mese'!$A:$A,Generale!$A22,'Ore-Mese'!$B:$B,VALUE(RIGHT(Generale!H$3,1))) -> 0 | I22: =SUMIFS('Ore-Mese'!$D:$D,'Ore-Mese'!$A:$A,Generale!$A22,'Ore-Mese'!$B:$B,VALUE(RIGHT(Generale!I$3,1))) -> 0 | J22: =SUM(F22:I22) -> 0
E23: =_xlfn.IFNA(INDEX($Q$5:$R$7,MATCH(D23,$L$5:$L$7,0),MATCH($B$1,$Q$4:$R$4,0)),0) -> 0 | F23: =SUMIFS('Ore-Mese'!$D:$D,'Ore-Mese'!$A:$A,Generale!$A23,'Ore-Mese'!$B:$B,VALUE(RIGHT(Generale!F$3,1))) -> 0 | G23: =SUMIFS('Ore-Mese'!$D:$D,'Ore-Mese'!$A:$A,Generale!$A23,'Ore-Mese'!$B:$B,VALUE(RIGHT(Generale!G$3,1))) -> 0 | H23: =SUMIFS('Ore-Mese'!$D:$D,'Ore-Mese'!$A:$A,Generale!$A23,'Ore-Mese'!$B:$B,VALUE(RIGHT(Generale!H$3,1))) -> 0 | I23: =SUMIFS('Ore-Mese'!$D:$D,'Ore-Mese'!$A:$A,Generale!$A23,'Ore-Mese'!$B:$B,VALUE(RIGHT(Generale!I$3,1))) -> 0 | J23: =SUM(F23:I23) -> 0
E24: =_xlfn.IFNA(INDEX($Q$5:$R$7,MATCH(D24,$L$5:$L$7,0),MATCH($B$1,$Q$4:$R$4,0)),0) -> 0 | F24: =SUMIFS('Ore-Mese'!$D:$D,'Ore-Mese'!$A:$A,Generale!$A24,'Ore-Mese'!$B:$B,VALUE(RIGHT(Generale!F$3,1))) -> 0 | G24: =SUMIFS('Ore-Mese'!$D:$D,'Ore-Mese'!$A:$A,Generale!$A24,'Ore-Mese'!$B:$B,VALUE(RIGHT(Generale!G$3,1))) -> 0 | H24: =SUMIFS('Ore-Mese'!$D:$D,'Ore-Mese'!$A:$A,Generale!$A24,'Ore-Mese'!$B:$B,VALUE(RIGHT(Generale!H$3,1))) -> 0 | I24: =SUMIFS('Ore-Mese'!$D:$D,'Ore-Mese'!$A:$A,Generale!$A24,'Ore-Mese'!$B:$B,VALUE(RIGHT(Generale!I$3,1))) -> 0 | J24: =SUM(F24:I24) -> 0
E25: =_xlfn.IFNA(INDEX($Q$5:$R$7,MATCH(D25,$L$5:$L$7,0),MATCH($B$1,$Q$4:$R$4,0)),0) -> 0 | F25: =SUMIFS('Ore-Mese'!$D:$D,'Ore-Mese'!$A:$A,Generale!$A25,'Ore-Mese'!$B:$B,VALUE(RIGHT(Generale!F$3,1))) -> 0 | G25: =SUMIFS('Ore-Mese'!$D:$D,'Ore-Mese'!$A:$A,Generale!$A25,'Ore-Mese'!$B:$B,VALUE(RIGHT(Generale!G$3,1))) -> 0 | H25: =SUMIFS('Ore-Mese'!$D:$D,'Ore-Mese'!$A:$A,Generale!$A25,'Ore-Mese'!$B:$B,VALUE(RIGHT(Generale!H$3,1))) -> 0 | I25: =SUMIFS('Ore-Mese'!$D:$D,'Ore-Mese'!$A:$A,Generale!$A25,'Ore-Mese'!$B:$B,VALUE(RIGHT(Generale!I$3,1))) -> 0 | J25: =SUM(F25:I25) -> 0
E26: =_xlfn.IFNA(INDEX($Q$5:$R$7,MATCH(D26,$L$5:$L$7,0),MATCH($B$1,$Q$4:$R$4,0)),0) -> 0 | F26: =SUMIFS('Ore-Mese'!$D:$D,'Ore-Mese'!$A:$A,Generale!$A26,'Ore-Mese'!$B:$B,VALUE(RIGHT(Generale!F$3,1))) -> 0 | G26: =SUMIFS('Ore-Mese'!$D:$D,'Ore-Mese'!$A:$A,Generale!$A26,'Ore-Mese'!$B:$B,VALUE(RIGHT(Generale!G$3,1))) -> 0 | H26: =SUMIFS('Ore-Mese'!$D:$D,'Ore-Mese'!$A:$A,Generale!$A26,'Ore-Mese'!$B:$B,VALUE(RIGHT(Generale!H$3,1))) -> 0 | I26: =SUMIFS('Ore-Mese'!$D:$D,'Ore-Mese'!$A:$A,Generale!$A26,'Ore-Mese'!$B:$B,VALUE(RIGHT(Generale!I$3,1))) -> 0 | J26: =SUM(F26:I26) -> 0
E27: =_xlfn.IFNA(INDEX($Q$5:$R$7,MATCH(D27,$L$5:$L$7,0),MATCH($B$1,$Q$4:$R$4,0)),0) -> 0 | F27: =SUMIFS('Ore-Mese'!$D:$D,'Ore-Mese'!$A:$A,Generale!$A27,'Ore-Mese'!$B:$B,VALUE(RIGHT(Generale!F$3,1))) -> 0 | G27: =SUMIFS('Ore-Mese'!$D:$D,'Ore-Mese'!$A:$A,Generale!$A27,'Ore-Mese'!$B:$B,VALUE(RIGHT(Generale!G$3,1))) -> 0 | H27: =SUMIFS('Ore-Mese'!$D:$D,'Ore-Mese'!$A:$A,Generale!$A27,'Ore-Mese'!$B:$B,VALUE(RIGHT(Generale!H$3,1))) -> 0 | I27: =SUMIFS('Ore-Mese'!$D:$D,'Ore-Mese'!$A:$A,Generale!$A27,'Ore-Mese'!$B:$B,VALUE(RIGHT(Generale!I$3,1))) -> 0 | J27: =SUM(F27:I27) -> 0
A28: Total | E28: =SUBTOTAL(101,Table5[Costo Orario (€/h)]) -> 22.708333 | F28: =SUBTOTAL(109,Table5[Ore Anno 1]) -> 6354.4 | G28: =SUBTOTAL(109,Table5[Ore Anno 2]) -> 7584.6 | H28: =SUBTOTAL(109,Table5[Ore Anno 3]) -> 5299.8 | I28: =SUBTOTAL(109,Table5[Ore Anno 4]) -> 4569.8 | J28: =SUBTOTAL(109,Table5[Totale Ore]) -> 23808.6
A31: Nominativo / Risorsa | B31: Column1 | C31: Ruolo | D31: Fascia di Livello | E31: Costo Orario (€/h) | F31: Anno 1 | G31: Anno 2 | H31: Anno 3 | I31: Anno 4 | J31: Totale €
A32: =A4 -> Andretto Elia | B32: =B4 -> NDRLEI98H26E063K | C32: =C4 -> CTER | D32: =D4 -> BASSO | E32: =E4 -> 29 | F32: =F4*$E4 -> 4593.6 | G32: =G4*$E4 -> 2583.9 | H32: =H4*$E4 -> 2583.9 | I32: =I4*$E4 -> 4593.6 | J32: =SUM(F32:I32) -> 14355
A33: =A5 -> Bozzi Roberto | B33: =B5 -> BZZRRT67H19F205U | C33: =C5 -> CTER | D33: =D5 -> BASSO | E33: =E5 -> 29 | F33: =F5*$E5 -> 4593.6 | G33: =G5*$E5 -> 2583.9 | H33: =H5*$E5 -> 2583.9 | I33: =I5*$E5 -> 4593.6 | J33: =SUM(F33:I33) -> 14355
A34: =A6 -> Caimmi Marco | B34: =B6 -> CMMMRC68C12F205K | C34: =C6 -> I ricercatore | D34: =D6 -> ALTO | E34: =E6 -> 55 | F34: =F6*$E6 -> 30250 | G34: =G6*$E6 -> 7260 | H34: =H6*$E6 -> 0 | I34: =I6*$E6 -> 0 | J34: =SUM(F34:I34) -> 37510
A35: =A7 -> Chizzoli Guido | B35: =B7 -> CHZGDU78R25D142Y | C35: =C7 -> Ricercatore III | D35: =D7 -> MEDIO | E35: =E7 -> 33 | F35: =F7*$E7 -> 4174.5 | G35: =G7*$E7 -> 0 | H35: =H7*$E7 -> 0 | I35: =I7*$E7 -> 0 | J35: =SUM(F35:I35) -> 4174.5
A36: =A8 -> Dinon Tito | B36: =B8 -> DNNTTI86M09C933W | C36: =C8 -> CTER | D36: =D8 -> BASSO | E36: =E8 -> 29 | F36: =F8*$E8 -> 4593.6 | G36: =G8*$E8 -> 4593.6 | H36: =H8*$E8 -> 3285.7 | I36: =I8*$E8 -> 2583.9 | J36: =SUM(F36:I36) -> 15056.8
A37: =A9 -> Mottura Stefano | B37: =B9 -> MTTSFN70L14F205T | C37: =C9 -> I Tecnologo | D37: =D9 -> ALTO | E37: =E9 -> 55 | F37: =F9*$E9 -> 32972.5 | G37: =G9*$E9 -> 32972.5 | H37: =H9*$E9 -> 23655.5 | I37: =I9*$E9 -> 18634 | J37: =SUM(F37:I37) -> 108234.5
A38: =A10 -> Pedrocchi Nicola | B38: =B10 -> PDRNCL79H26E333U | C38: =C10 -> Dir. Ricerca | D38: =D10 -> ALTO | E38: =E10 -> 55 | F38: =F10*$E10 -> 76230 | G38: =G10*$E10 -> 76230 | H38: =H10*$E10 -> 60742 | I38: =I10*$E10 -> 36300 | J38: =SUM(F38:I38) -> 249502
A39: =A11 -> Silva Fabrizio | B39: =B11 -> SLVFRZ80S19L872K | C39: =C11 -> Tecnologo III | D39: =D11 -> MEDIO | E39: =E11 -> 33 | F39: =F11*$E11 -> 4174.5 | G39: =G11*$E11 -> 0 | H39: =H11*$E11 -> 0 | I39: =I11*$E11 -> 0 | J39: =SUM(F39:I39) -> 4174.5
A40: =A12 -> Spena Pier Raffaele | B40: =B12 -> SPNPRF70T12F839E | C40: =C12 -> CTER | D40: =D12 -> BASSO | E40: =E12 -> 29 | F40: =F12*$E12 -> 4593.6 | G40: =G12*$E12 -> 4593.6 | H40: =H12*$E12 -> 3285.7 | I40: =I12*$E12 -> 2583.9 | J40: =SUM(F40:I40) -> 15056.8
A41: =A13 -> Villagrossi Enrico | B41: =B13 -> VLLNRC86R08E897T | C41: =C13 -> Ricercatore | D41: =D13 -> MEDIO | E41: =E13 -> 33 | F41: =F13*$E13 -> 15486.9 | G41: =G13*$E13 -> 8385.3 | H41: =H13*$E13 -> 5989.5 | I41: =I13*$E13 -> 0 | J41: =SUM(F41:I41) -> 29861.7
A42: =A14 -> Contratto di Ricerca 1 | B42: =B14 -> 0 | C42: =C14 -> Ricercatore | D42: =D14 -> MEDIO | E42: =E14 -> 33 | F42: =F14*$E14 -> 20790 | G42: =G14*$E14 -> 45738 | H42: =H14*$E14 -> 36300 | I42: =I14*$E14 -> 23100 | J42: =SUM(F42:I42) -> 125928
A43: =A15 -> Contratto di Ricerca 2 | B43: =B15 -> 0 | C43: =C15 -> Ricercatore | D43: =D15 -> MEDIO | E43: =E15 -> 33 | F43: =F15*$E15 -> 0 | G43: =G15*$E15 -> 18480 | H43: =H15*$E15 -> 22869 | I43: =I15*$E15 -> 32670 | J43: =SUM(F43:I43) -> 74019
...

Sheet Ore-Mese
A2: Risorsa | B2: Anno | C2: Mese | D2: Valore distribuito | F2: 2026 | G2: 2027 | H2: 2028 | I2: 2029
A3: Caimmi Marco | B3: 1 | C3: Febbraio | D3: 50
A4: Caimmi Marco | B4: 1 | C4: Marzo | D4: 50
A5: Caimmi Marco | B5: 1 | C5: Aprile | D5: 50
A6: Caimmi Marco | B6: 1 | C6: Maggio | D6: 50
A7: Caimmi Marco | B7: 1 | C7: Giugno | D7: 50
A8: Caimmi Marco | B8: 1 | C8: Luglio | D8: 50
A9: Caimmi Marco | B9: 1 | C9: Settembre | D9: 50
A10: Caimmi Marco | B10: 1 | C10: Ottobre | D10: 50
A11: Caimmi Marco | B11: 1 | C11: Novembre | D11: 50
A12: Caimmi Marco | B12: 1 | C12: Dicembre | D12: 50
A13: Caimmi Marco | B13: 1 | C13: Gennaio | D13: 50
A14: Caimmi Marco | B14: 2 | C14: Febbraio | D14: 12
... A45: Caimmi Marco | B45: 4 | C45: Dicembre | D45: 0
A46: Caimmi Marco | B46: 4 | C46: Gennaio | D46: 0 | E46: =SUM(D3:D46) -> 682
A48: Spena Pier Raffaele | B48: 1 | C48: Febbraio | D48: 14.4
A49: Spena Pier Raffaele | B49: 1 | C49: Marzo | D49: 14.4
A50: Spena Pier Raffaele | B50: 1 | C50: Aprile | D50: 14.4
A51: Spena Pier Raffaele | B51: 1 | C51: Maggio | D51: 14.4
A52: Spena Pier Raffaele | B52: 1 | C52: Giugno | D52: 14.4
A53: Spena Pier Raffaele | B53: 1 | C53: Luglio | D53: 14.4
A54: Spena Pier Raffaele | B54: 1 | C54: Settembre | D54: 14.4
A55: Spena Pier Raffaele | B55: 1 | C55: Ottobre | D55: 14.4
A56: Spena Pier Raffaele | B56: 1 | C56: Novembre | D56: 14.4
A57: Spena Pier Raffaele | B57: 1 | C57: Dicembre | D57: 14.4
A58: Spena Pier Raffaele | B58: 1 | C58: Gennaio | D58: 14.4
A59: Spena Pier Raffaele | B59: 2 | C59: Febbraio | D59: 14.4
... A90: Spena Pier Raffaele | B90: 4 | C90: Dicembre | D90: 8.1
A91: Spena Pier Raffaele | B91: 4 | C91: Gennaio | D91: 8.1 | E91: =SUM(D48:D91) -> 519.2
A93: Andretto Elia | B93: 1 | C93: Febbraio | D93: 14.4
A94: Andretto Elia | B94: 1 | C94: Marzo | D94: 14.4
A95: Andretto Elia | B95: 1 | C95: Aprile | D95: 14.4
A96: Andretto Elia | B96: 1 | C96: Maggio | D96: 14.4
A97: Andretto Elia | B97: 1 | C97: Giugno | D97: 14.4
A98: Andretto Elia | B98: 1 | C98: Luglio | D98: 14.4
A99: Andretto Elia | B99: 1 | C99: Settembre | D99: 14.4
A100: Andretto Elia | B100: 1 | C100: Ottobre | D100: 14.4
A101: Andretto Elia | B101: 1 | C101: Novembre | D101: 14.4
A102: Andretto Elia | B102: 1 | C102: Dicembre | D102: 14.4
A103: Andretto Elia | B103: 1 | C103: Gennaio | D103: 14.4
...

Sheet Mesi-Uomo
A1: Nominativo / Risorsa | B1: Ruolo | C1: PM Anno 1 | D1: PM Anno 2 | E1: PM Anno 3 | F1: PM Anno 4 | G1: Totale PM | H1: Totale Ore (rif.)
A2: =Generale!A4 -> Andretto Elia | B2: =Generale!C4 -> CTER | C2: =SUMIFS('Ore-Mese'!$D:$D,'Ore-Mese'!$A:$A,'Mesi-Uomo'!$A2,'Ore-Mese'!$B:$B,VALUE(RIGHT('Mesi-Uomo'!C$1,1)))/1502*12 -> 1.2655126 | D2: =SUMIFS('Ore-Mese'!$D:$D,'Ore-Mese'!$A:$A,'Mesi-Uomo'!$A2,'Ore-Mese'!$B:$B,VALUE(RIGHT('Mesi-Uomo'!D$1,1)))/1502*12 -> 0.71185087 | E2: =SUMIFS('Ore-Mese'!$D:$D,'Ore-Mese'!$A:$A,'Mesi-Uomo'!$A2,'Ore-Mese'!$B:$B,VALUE(RIGHT('Mesi-Uomo'!E$1,1)))/1502*12 -> 0.71185087 | F2: =SUMIFS('Ore-Mese'!$D:$D,'Ore-Mese'!$A:$A,'Mesi-Uomo'!$A2,'Ore-Mese'!$B:$B,VALUE(RIGHT('Mesi-Uomo'!F$1,1)))/1502*12 -> 1.2655126 | G2: =SUM(C2:F2) -> 3.954727 | H2: =SUMIF('Ore-Mese'!$A:$A,'Mesi-Uomo'!$A2,'Ore-Mese'!$D:$D) -> 495
A3: =Generale!A5 -> Bozzi Roberto | B3: =Generale!C5 -> CTER | C3: =SUMIFS('Ore-Mese'!$D:$D,'Ore-Mese'!$A:$A,'Mesi-Uomo'!$A3,'Ore-Mese'!$B:$B,VALUE(RIGHT('Mesi-Uomo'!C$1,1)))/1502*12 -> 1.2655126 | D3: =SUMIFS('Ore-Mese'!$D:$D,'Ore-Mese'!$A:$A,'Mesi-Uomo'!$A3,'Ore-Mese'!$B:$B,VALUE(RIGHT('Mesi-Uomo'!D$1,1)))/1502*12 -> 0.71185087 | E3: =SUMIFS('Ore-Mese'!$D:$D,'Ore-Mese'!$A:$A,'Mesi-Uomo'!$A3,'Ore-Mese'!$B:$B,VALUE(RIGHT('Mesi-Uomo'!E$1,1)))/1502*12 -> 0.71185087 | F3: =SUMIFS('Ore-Mese'!$D:$D,'Ore-Mese'!$A:$A,'Mesi-Uomo'!$A3,'Ore-Mese'!$B:$B,VALUE(RIGHT('Mesi-Uomo'!F$1,1)))/1502*12 -> 1.2655126 | G3: =SUM(C3:F3) -> 3.954727 | H3: =SUMIF('Ore-Mese'!$A:$A,'Mesi-Uomo'!$A3,'Ore-Mese'!$D:$D) -> 495
A4: =Generale!A6 -> Caimmi Marco | B4: =Generale!C6 -> I ricercatore | C4: =SUMIFS('Ore-Mese'!$D:$D,'Ore-Mese'!$A:$A,'Mesi-Uomo'!$A4,'Ore-Mese'!$B:$B,VALUE(RIGHT('Mesi-Uomo'!C$1,1)))/1502*12 -> 4.3941411 | D4: =SUMIFS('Ore-Mese'!$D:$D,'Ore-Mese'!$A:$A,'Mesi-Uomo'!$A4,'Ore-Mese'!$B:$B,VALUE(RIGHT('Mesi-Uomo'!D$1,1)))/1502*12 -> 1.0545939 | E4: =SUMIFS('Ore-Mese'!$D:$D,'Ore-Mese'!$A:$A,'Mesi-Uomo'!$A4,'Ore-Mese'!$B:$B,VALUE(RIGHT('Mesi-Uomo'!E$1,1)))/1502*12 -> 0 | F4: =SUMIFS('Ore-Mese'!$D:$D,'Ore-Mese'!$A:$A,'Mesi-Uomo'!$A4,'Ore-Mese'!$B:$B,VALUE(RIGHT('Mesi-Uomo'!F$1,1)))/1502*12 -> 0 | G4: =SUM(C4:F4) -> 5.448735 | H4: =SUMIF('Ore-Mese'!$A:$A,'Mesi-Uomo'!$A4,'Ore-Mese'!$D:$D) -> 682
A5: =Generale!A7 -> Chizzoli Guido | B5: =Generale!C7 -> Ricercatore III | C5: =SUMIFS('Ore-Mese'!$D:$D,'Ore-Mese'!$A:$A,'Mesi-Uomo'!$A5,'Ore-Mese'!$B:$B,VALUE(RIGHT('Mesi-Uomo'!C$1,1)))/1502*12 -> 1.0106525 | D5: =SUMIFS('Ore-Mese'!$D:$D,'Ore-Mese'!$A:$A,'Mesi-Uomo'!$A5,'Ore-Mese'!$B:$B,VALUE(RIGHT('Mesi-Uomo'!D$1,1)))/1502*12 -> 0 | E5: =SUMIFS('Ore-Mese'!$D:$D,'Ore-Mese'!$A:$A,'Mesi-Uomo'!$A5,'Ore-Mese'!$B:$B,VALUE(RIGHT('Mesi-Uomo'!E$1,1)))/1502*12 -> 0 | F5: =SUMIFS('Ore-Mese'!$D:$D,'Ore-Mese'!$A:$A,'Mesi-Uomo'!$A5,'Ore-Mese'!$B:$B,VALUE(RIGHT('Mesi-Uomo'!F$1,1)))/1502*12 -> 0 | G5: =SUM(C5:F5) -> 1.0106525 | H5: =SUMIF('Ore-Mese'!$A:$A,'Mesi-Uomo'!$A5,'Ore-Mese'!$D:$D) -> 126.5
A6: =Generale!A8 -> Dinon Tito | B6: =Generale!C8 -> CTER | C6: =SUMIFS('Ore-Mese'!$D:$D,'Ore-Mese'!$A:$A,'Mesi-Uomo'!$A6,'Ore-Mese'!$B:$B,VALUE(RIGHT('Mesi-Uomo'!C$1,1)))/1502*12 -> 1.2655126 | D6: =SUMIFS('Ore-Mese'!$D:$D,'Ore-Mese'!$A:$A,'Mesi-Uomo'!$A6,'Ore-Mese'!$B:$B,VALUE(RIGHT('Mesi-Uomo'!D$1,1)))/1502*12 -> 1.2655126 | E6: =SUMIFS('Ore-Mese'!$D:$D,'Ore-Mese'!$A:$A,'Mesi-Uomo'!$A6,'Ore-Mese'!$B:$B,VALUE(RIGHT('Mesi-Uomo'!E$1,1)))/1502*12 -> 0.90519308 | F6: =SUMIFS('Ore-Mese'!$D:$D,'Ore-Mese'!$A:$A,'Mesi-Uomo'!$A6,'Ore-Mese'!$B:$B,VALUE(RIGHT('Mesi-Uomo'!F$1,1)))/1502*12 -> 0.71185087 | G6: =SUM(C6:F6) -> 4.1480692 | H6: =SUMIF('Ore-Mese'!$A:$A,'Mesi-Uomo'!$A6,'Ore-Mese'!$D:$D) -> 519.2
A7: =Generale!A9 -> Mottura Stefano | B7: =Generale!C9 -> I Tecnologo | C7: =SUMIFS('Ore-Mese'!$D:$D,'Ore-Mese'!$A:$A,'Mesi-Uomo'!$A7,'Ore-Mese'!$B:$B,VALUE(RIGHT('Mesi-Uomo'!C$1,1)))/1502*12 -> 4.7896138 | D7: =SUMIFS('Ore-Mese'!$D:$D,'Ore-Mese'!$A:$A,'Mesi-Uomo'!$A7,'Ore-Mese'!$B:$B,VALUE(RIGHT('Mesi-Uomo'!D$1,1)))/1502*12 -> 4.7896138 | E7: =SUMIFS('Ore-Mese'!$D:$D,'Ore-Mese'!$A:$A,'Mesi-Uomo'!$A7,'Ore-Mese'!$B:$B,VALUE(RIGHT('Mesi-Uomo'!E$1,1)))/1502*12 -> 3.4362184 | F7: =SUMIFS('Ore-Mese'!$D:$D,'Ore-Mese'!$A:$A,'Mesi-Uomo'!$A7,'Ore-Mese'!$B:$B,VALUE(RIGHT('Mesi-Uomo'!F$1,1)))/1502*12 -> 2.7067909 | G7: =SUM(C7:F7) -> 15.722237 | H7: =SUMIF('Ore-Mese'!$A:$A,'Mesi-Uomo'!$A7,'Ore-Mese'!$D:$D) -> 1967.9
A8: =Generale!A10 -> Pedrocchi Nicola | B8: =Generale!C10 -> Dir. Ricerca | C8: =SUMIFS('Ore-Mese'!$D:$D,'Ore-Mese'!$A:$A,'Mesi-Uomo'!$A8,'Ore-Mese'!$B:$B,VALUE(RIGHT('Mesi-Uomo'!C$1,1)))/1502*12 -> 11.073236 | D8: =SUMIFS('Ore-Mese'!$D:$D,'Ore-Mese'!$A:$A,'Mesi-Uomo'!$A8,'Ore-Mese'!$B:$B,VALUE(RIGHT('Mesi-Uomo'!D$1,1)))/1502*12 -> 11.073236 | E8: =SUMIFS('Ore-Mese'!$D:$D,'Ore-Mese'!$A:$A,'Mesi-Uomo'!$A8,'Ore-Mese'!$B:$B,VALUE(RIGHT('Mesi-Uomo'!E$1,1)))/1502*12 -> 8.8234354 | F8: =SUMIFS('Ore-Mese'!$D:$D,'Ore-Mese'!$A:$A,'Mesi-Uomo'!$A8,'Ore-Mese'!$B:$B,VALUE(RIGHT('Mesi-Uomo'!F$1,1)))/1502*12 -> 5.2729694 | G8: =SUM(C8:F8) -> 36.242876 | H8: =SUMIF('Ore-Mese'!$A:$A,'Mesi-Uomo'!$A8,'Ore-Mese'!$D:$D) -> 4536.4
A9: =Generale!A11 -> Silva Fabrizio | B9: =Generale!C11 -> Tecnologo III | C9: =SUMIFS('Ore-Mese'!$D:$D,'Ore-Mese'!$A:$A,'Mesi-Uomo'!$A9,'Ore-Mese'!$B:$B,VALUE(RIGHT('Mesi-Uomo'!C$1,1)))/1502*12 -> 1.0106525 | D9: =SUMIFS('Ore-Mese'!$D:$D,'Ore-Mese'!$A:$A,'Mesi-Uomo'!$A9,'Ore-Mese'!$B:$B,VALUE(RIGHT('Mesi-Uomo'!D$1,1)))/1502*12 -> 0 | E9: =SUMIFS('Ore-Mese'!$D:$D,'Ore-Mese'!$A:$A,'Mesi-Uomo'!$A9,'Ore-Mese'!$B:$B,VALUE(RIGHT('Mesi-Uomo'!E$1,1)))/1502*12 -> 0 | F9: =SUMIFS('Ore-Mese'!$D:$D,'Ore-Mese'!$A:$A,'Mesi-Uomo'!$A9,'Ore-Mese'!$B:$B,VALUE(RIGHT('Mesi-Uomo'!F$1,1)))/1502*12 -> 0 | G9: =SUM(C9:F9) -> 1.0106525 | H9: =SUMIF('Ore-Mese'!$A:$A,'Mesi-Uomo'!$A9,'Ore-Mese'!$D:$D) -> 126.5
A10: =Generale!A12 -> Spena Pier Raffaele | B10: =Generale!C12 -> CTER | C10: =SUMIFS('Ore-Mese'!$D:$D,'Ore-Mese'!$A:$A,'Mesi-Uomo'!$A10,'Ore-Mese'!$B:$B,VALUE(RIGHT('Mesi-Uomo'!C$1,1)))/1502*12 -> 1.2655126 | D10: =SUMIFS('Ore-Mese'!$D:$D,'Ore-Mese'!$A:$A,'Mesi-Uomo'!$A10,'Ore-Mese'!$B:$B,VALUE(RIGHT('Mesi-Uomo'!D$1,1)))/1502*12 -> 1.2655126 | E10: =SUMIFS('Ore-Mese'!$D:$D,'Ore-Mese'!$A:$A,'Mesi-Uomo'!$A10,'Ore-Mese'!$B:$B,VALUE(RIGHT('Mesi-Uomo'!E$1,1)))/1502*12 -> 0.90519308 | F10: =SUMIFS('Ore-Mese'!$D:$D,'Ore-Mese'!$A:$A,'Mesi-Uomo'!$A10,'Ore-Mese'!$B:$B,VALUE(RIGHT('Mesi-Uomo'!F$1,1)))/1502*12 -> 0.71185087 | G10: =SUM(C10:F10) -> 4.1480692 | H10: =SUMIF('Ore-Mese'!$A:$A,'Mesi-Uomo'!$A10,'Ore-Mese'!$D:$D) -> 519.2
A11: =Generale!A13 -> Villagrossi Enrico | B11: =Generale!C13 -> Ricercatore | C11: =SUMIFS('Ore-Mese'!$D:$D,'Ore-Mese'!$A:$A,'Mesi-Uomo'!$A11,'Ore-Mese'!$B:$B,VALUE(RIGHT('Mesi-Uomo'!C$1,1)))/1502*12 -> 3.7494008 | D11: =SUMIFS('Ore-Mese'!$D:$D,'Ore-Mese'!$A:$A,'Mesi-Uomo'!$A11,'Ore-Mese'!$B:$B,VALUE(RIGHT('Mesi-Uomo'!D$1,1)))/1502*12 -> 2.0300932 | E11: =SUMIFS('Ore-Mese'!$D:$D,'Ore-Mese'!$A:$A,'Mesi-Uomo'!$A11,'Ore-Mese'!$B:$B,VALUE(RIGHT('Mesi-Uomo'!E$1,1)))/1502*12 -> 1.4500666 | F11: =SUMIFS('Ore-Mese'!$D:$D,'Ore-Mese'!$A:$A,'Mesi-Uomo'!$A11,'Ore-Mese'!$B:$B,VALUE(RIGHT('Mesi-Uomo'!F$1,1)))/1502*12 -> 0 | G11: =SUM(C11:F11) -> 7.2295606 | H11: =SUMIF('Ore-Mese'!$A:$A,'Mesi-Uomo'!$A11,'Ore-Mese'!$D:$D) -> 904.9
A12: =Generale!A14 -> Contratto di Ricerca 1 | B12: =Generale!C14 -> Ricercatore | C12: =SUMIFS('Ore-Mese'!$D:$D,'Ore-Mese'!$A:$A,'Mesi-Uomo'!$A12,'Ore-Mese'!$B:$B,VALUE(RIGHT('Mesi-Uomo'!C$1,1)))/1502*12 -> 5.0332889 | D12: =SUMIFS('Ore-Mese'!$D:$D,'Ore-Mese'!$A:$A,'Mesi-Uomo'!$A12,'Ore-Mese'!$B:$B,VALUE(RIGHT('Mesi-Uomo'!D$1,1)))/1502*12 -> 11.073236 | E12: =SUMIFS('Ore-Mese'!$D:$D,'Ore-Mese'!$A:$A,'Mesi-Uomo'!$A12,'Ore-Mese'!$B:$B,VALUE(RIGHT('Mesi-Uomo'!E$1,1)))/1502*12 -> 8.7882823 | F12: =SUMIFS('Ore-Mese'!$D:$D,'Ore-Mese'!$A:$A,'Mesi-Uomo'!$A12,'Ore-Mese'!$B:$B,VALUE(RIGHT('Mesi-Uomo'!F$1,1)))/1502*12 -> 5.5925433 | G12: =SUM(C12:F12) -> 30.48735 | H12: =SUMIF('Ore-Mese'!$A:$A,'Mesi-Uomo'!$A12,'Ore-Mese'!$D:$D) -> 3816
A13: =Generale!A15 -> Contratto di Ricerca 2 | B13: =Generale!C15 -> Ricercatore | C13: =SUMIFS('Ore-Mese'!$D:$D,'Ore-Mese'!$A:$A,'Mesi-Uomo'!$A13,'Ore-Mese'!$B:$B,VALUE(RIGHT('Mesi-Uomo'!C$1,1)))/1502*12 -> 0 | D13: =SUMIFS('Ore-Mese'!$D:$D,'Ore-Mese'!$A:$A,'Mesi-Uomo'!$A13,'Ore-Mese'!$B:$B,VALUE(RIGHT('Mesi-Uomo'!D$1,1)))/1502*12 -> 4.4740346 | E13: =SUMIFS('Ore-Mese'!$D:$D,'Ore-Mese'!$A:$A,'Mesi-Uomo'!$A13,'Ore-Mese'!$B:$B,VALUE(RIGHT('Mesi-Uomo'!E$1,1)))/1502*12 -> 5.5366178 | F13: =SUMIFS('Ore-Mese'!$D:$D,'Ore-Mese'!$A:$A,'Mesi-Uomo'!$A13,'Ore-Mese'!$B:$B,VALUE(RIGHT('Mesi-Uomo'!F$1,1)))/1502*12 -> 7.9094541 | G13: =SUM(C13:F13) -> 17.920107 | H13: =SUMIF('Ore-Mese'!$A:$A,'Mesi-Uomo'!$A13,'Ore-Mese'!$D:$D) -> 2243
... A23: =Generale!A25 -> 0 | B23: =Generale!C25 -> 0 | C23: =SUMIFS('Ore-Mese'!$D:$D,'Ore-Mese'!$A:$A,'Mesi-Uomo'!$A23,'Ore-Mese'!$B:$B,VALUE(RIGHT('Mesi-Uomo'!C$1,1)))/1502*12 -> 0 | D23: =SUMIFS('Ore-Mese'!$D:$D,'Ore-Mese'!$A:$A,'Mesi-Uomo'!$A23,'Ore-Mese'!$B:$B,VALUE(RIGHT('Mesi-Uomo'!D$1,1)))/1502*12 -> 0 | E23: =SUMIFS('Ore-Mese'!$D:$D,'Ore-Mese'!$A:$A,'Mesi-Uomo'!$A23,'Ore-Mese'!$B:$B,VALUE(RIGHT('Mesi-Uomo'!E$1,1)))/1502*12 -> 0 | F23: =SUMIFS('Ore-Mese'!$D:$D,'Ore-Mese'!$A:$A,'Mesi-Uomo'!$A23,'Ore-Mese'!$B:$B,VALUE(RIGHT('Mesi-Uomo'!F$1,1)))/1502*12 -> 0 | G23: =SUM(C23:F23) -> 0 | H23: =SUMIF('Ore-Mese'!$A:$A,'Mesi-Uomo'!$A23,'Ore-Mese'!$D:$D) -> 0
A24: TOTALE | C24: =SUM(C2:C12) -> 36.123036 | D24: =SUM(D2:D12) -> 33.975499 | E24: =SUM(E2:E12) -> 25.732091 | F24: =SUM(F2:F12) -> 17.527031 | G24: =SUM(G2:G12) -> 113.35766 | H24: =SUM(H2:H12) -> 14188.6
